{
  "nbformat": 4,
  "nbformat_minor": 0,
  "metadata": {
    "colab": {
      "provenance": [],
      "authorship_tag": "ABX9TyOozq9+mfLh/lHua+k1G3lW",
      "include_colab_link": true
    },
    "kernelspec": {
      "name": "python3",
      "display_name": "Python 3"
    },
    "language_info": {
      "name": "python"
    }
  },
  "cells": [
    {
      "cell_type": "markdown",
      "metadata": {
        "id": "view-in-github",
        "colab_type": "text"
      },
      "source": [
        "<a href=\"https://colab.research.google.com/github/Abdulrahman-Aljasser/My-projects/blob/main/%D9%85%D8%B1%D8%B4%D8%AF_BOT.ipynb\" target=\"_parent\"><img src=\"https://colab.research.google.com/assets/colab-badge.svg\" alt=\"Open In Colab\"/></a>"
      ]
    },
    {
      "cell_type": "code",
      "execution_count": null,
      "metadata": {
        "colab": {
          "base_uri": "https://localhost:8080/",
          "height": 647
        },
        "id": "P-m-uzzpa0Nd",
        "outputId": "cf46bafe-f7f7-4dcd-927f-1f14975dc42f"
      },
      "outputs": [
        {
          "output_type": "stream",
          "name": "stdout",
          "text": [
            "Collecting python-dotenv\n",
            "  Downloading python_dotenv-1.1.0-py3-none-any.whl.metadata (24 kB)\n",
            "Downloading python_dotenv-1.1.0-py3-none-any.whl (20 kB)\n",
            "Installing collected packages: python-dotenv\n",
            "Successfully installed python-dotenv-1.1.0\n",
            "Collecting python-telegram-bot\n",
            "  Downloading python_telegram_bot-22.0-py3-none-any.whl.metadata (17 kB)\n",
            "Requirement already satisfied: pandas in /usr/local/lib/python3.11/dist-packages (2.2.2)\n",
            "Requirement already satisfied: httpx~=0.27 in /usr/local/lib/python3.11/dist-packages (from python-telegram-bot) (0.28.1)\n",
            "Requirement already satisfied: numpy>=1.23.2 in /usr/local/lib/python3.11/dist-packages (from pandas) (2.0.2)\n",
            "Requirement already satisfied: python-dateutil>=2.8.2 in /usr/local/lib/python3.11/dist-packages (from pandas) (2.9.0.post0)\n",
            "Requirement already satisfied: pytz>=2020.1 in /usr/local/lib/python3.11/dist-packages (from pandas) (2025.2)\n",
            "Requirement already satisfied: tzdata>=2022.7 in /usr/local/lib/python3.11/dist-packages (from pandas) (2025.2)\n",
            "Requirement already satisfied: anyio in /usr/local/lib/python3.11/dist-packages (from httpx~=0.27->python-telegram-bot) (4.9.0)\n",
            "Requirement already satisfied: certifi in /usr/local/lib/python3.11/dist-packages (from httpx~=0.27->python-telegram-bot) (2025.4.26)\n",
            "Requirement already satisfied: httpcore==1.* in /usr/local/lib/python3.11/dist-packages (from httpx~=0.27->python-telegram-bot) (1.0.9)\n",
            "Requirement already satisfied: idna in /usr/local/lib/python3.11/dist-packages (from httpx~=0.27->python-telegram-bot) (3.10)\n",
            "Requirement already satisfied: h11>=0.16 in /usr/local/lib/python3.11/dist-packages (from httpcore==1.*->httpx~=0.27->python-telegram-bot) (0.16.0)\n",
            "Requirement already satisfied: six>=1.5 in /usr/local/lib/python3.11/dist-packages (from python-dateutil>=2.8.2->pandas) (1.17.0)\n",
            "Requirement already satisfied: sniffio>=1.1 in /usr/local/lib/python3.11/dist-packages (from anyio->httpx~=0.27->python-telegram-bot) (1.3.1)\n",
            "Requirement already satisfied: typing_extensions>=4.5 in /usr/local/lib/python3.11/dist-packages (from anyio->httpx~=0.27->python-telegram-bot) (4.13.2)\n",
            "Downloading python_telegram_bot-22.0-py3-none-any.whl (673 kB)\n",
            "\u001b[2K   \u001b[90m━━━━━━━━━━━━━━━━━━━━━━━━━━━━━━━━━━━━━━━━\u001b[0m \u001b[32m673.5/673.5 kB\u001b[0m \u001b[31m8.8 MB/s\u001b[0m eta \u001b[36m0:00:00\u001b[0m\n",
            "\u001b[?25hInstalling collected packages: python-telegram-bot\n",
            "Successfully installed python-telegram-bot-22.0\n"
          ]
        },
        {
          "output_type": "error",
          "ename": "NameError",
          "evalue": "name 'app' is not defined",
          "traceback": [
            "\u001b[0;31m---------------------------------------------------------------------------\u001b[0m",
            "\u001b[0;31mNameError\u001b[0m                                 Traceback (most recent call last)",
            "\u001b[0;32m<ipython-input-7-efaa3fd44431>\u001b[0m in \u001b[0;36m<cell line: 0>\u001b[0;34m()\u001b[0m\n\u001b[1;32m      3\u001b[0m \u001b[0;32mimport\u001b[0m \u001b[0mnest_asyncio\u001b[0m\u001b[0;34m\u001b[0m\u001b[0;34m\u001b[0m\u001b[0m\n\u001b[1;32m      4\u001b[0m \u001b[0mnest_asyncio\u001b[0m\u001b[0;34m.\u001b[0m\u001b[0mapply\u001b[0m\u001b[0;34m(\u001b[0m\u001b[0;34m)\u001b[0m\u001b[0;34m\u001b[0m\u001b[0;34m\u001b[0m\u001b[0m\n\u001b[0;32m----> 5\u001b[0;31m \u001b[0mapp\u001b[0m\u001b[0;34m.\u001b[0m\u001b[0mrun_polling\u001b[0m\u001b[0;34m(\u001b[0m\u001b[0mnon_blocking\u001b[0m\u001b[0;34m=\u001b[0m\u001b[0;32mTrue\u001b[0m\u001b[0;34m)\u001b[0m\u001b[0;34m\u001b[0m\u001b[0;34m\u001b[0m\u001b[0m\n\u001b[0m\u001b[1;32m      6\u001b[0m \u001b[0;34m\u001b[0m\u001b[0m\n",
            "\u001b[0;31mNameError\u001b[0m: name 'app' is not defined"
          ]
        }
      ],
      "source": [
        "!pip install python-dotenv\n",
        "!pip install python-telegram-bot pandas\n",
        "import nest_asyncio\n",
        "nest_asyncio.apply()\n",
        "app.run_polling(non_blocking=True)\n",
        "\n"
      ]
    },
    {
      "cell_type": "code",
      "source": [
        "import nest_asyncio\n",
        "nest_asyncio.apply()\n",
        "\n",
        "import pandas as pd\n",
        "import os\n",
        "from telegram import Update, ReplyKeyboardMarkup, ReplyKeyboardRemove\n",
        "from telegram.ext import ApplicationBuilder, CommandHandler, MessageHandler, ContextTypes, filters\n",
        "from dotenv import load_dotenv\n",
        "import asyncio\n",
        "\n",
        "# تحميل البيئة\n",
        "load_dotenv()\n",
        "TOKEN = \"7766299556:AAF0hjxA63YSBht15hVLq6OrasM8Rowgzxk\"  # ضع التوكن الخاص بك هنا\n",
        "\n",
        "BASE_DIR = '/content'  # تعيين مسار المجلد في Google Colab\n",
        "\n",
        "# تحميل البيانات\n",
        "data_courses = pd.read_excel(os.path.join(BASE_DIR, 'المواد.xlsx'))\n",
        "data_sections = pd.read_excel(os.path.join(BASE_DIR, 'الشعب.xlsx'))\n",
        "\n",
        "# تنظيف البيانات\n",
        "data_courses.columns = data_courses.columns.str.strip()\n",
        "data_sections.columns = data_sections.columns.str.strip()\n",
        "\n",
        "# قائمة المواد الاختيارية لكل تخصص\n",
        "optional_files = {\n",
        "    'MIS': 'المواد الاختياريةmis.xlsx',\n",
        "    'MGT': 'المواد الاختياريةmgt.xlsx',\n",
        "    'MKT': 'المواد الاختياريةmkt.xlsx',\n",
        "    'FIN': 'المواد الاختياريةfin.xlsx',\n",
        "    'ACC': 'المواد الاختياريةacc.xlsx'\n",
        "}\n",
        "\n",
        "optional_data = {}\n",
        "for major, filename in optional_files.items():\n",
        "    file_path = os.path.join(BASE_DIR, filename)\n",
        "    if os.path.exists(file_path):\n",
        "        try:\n",
        "            df = pd.read_excel(file_path)\n",
        "            df.columns = df.columns.str.strip()\n",
        "            optional_data[major] = df\n",
        "        except Exception as e:\n",
        "            print(f\"حدث خطأ أثناء تحميل المواد الاختيارية لـ {major}: {e}\")\n",
        "    else:\n",
        "        optional_data[major] = None\n",
        "\n",
        "# التعامل مع بداية البوت\n",
        "async def start(update: Update, context: ContextTypes.DEFAULT_TYPE):\n",
        "    keyboard = [['📚 استعلام عن مادة', '📋 استعلام عن شعبة'],\n",
        "                ['📖 الخطة الدراسية', '📖 دليل خدمات الطالب'],\n",
        "                ['📋 المواد الاختيارية', '❌ خروج']]\n",
        "    reply_markup = ReplyKeyboardMarkup(keyboard, resize_keyboard=True)\n",
        "    await update.message.reply_text(\n",
        "        \"✉️ مرحبًا بك في بوت خدمة الطالب!\\nاختر الخدمة من الأزرار أو اكتب /start للقائمة الرئيسية.\\n- استعلام عن المواد والشُعب.\\n- استكشاف الخطة الدراسية.\\n- دليل خدمات الطالب.\\n- استكشاف المواد الاختيارية.\\n🚀 جاهزين نخدمك دائمًا!\",\n",
        "        reply_markup=reply_markup\n",
        "    )\n",
        "\n",
        "# التعامل مع قائمة المواد الاختيارية\n",
        "async def handle_optional_menu(update: Update, context: ContextTypes.DEFAULT_TYPE):\n",
        "    keyboard = [['تخصص MIS', 'تخصص MGT'],\n",
        "                ['تخصص MKT', 'تخصص FIN'],\n",
        "                ['تخصص ACC', '🔙 رجوع']]\n",
        "    reply_markup = ReplyKeyboardMarkup(keyboard, resize_keyboard=True)\n",
        "    await update.message.reply_text(\"📋 اختر القسم الذي تريد عرض مواده الاختيارية:\", reply_markup=reply_markup)\n",
        "\n",
        "# عرض المواد الاختيارية حسب التخصص\n",
        "async def show_optional_by_major(update: Update, major: str):\n",
        "    df = optional_data.get(major)\n",
        "    if df is None:\n",
        "        await update.message.reply_text(\"🚧 المواد الاختيارية لهذا التخصص لم تُضاف بعد.\")\n",
        "        return\n",
        "\n",
        "    msg = f\"📋 *المواد الاختيارية لتخصص {major}:*\\n\"\n",
        "    for _, row in df.iterrows():\n",
        "        msg += (\n",
        "            f\"- {row['رمز المادة']} - {row['اسم المادة']}\\n\"\n",
        "            f\"  • المتطلبات: {row['المتطلبات']}\\n\"\n",
        "            f\"  • عدد الساعات: {row['عدد الساعات']}\\n\\n\"\n",
        "        )\n",
        "    await update.message.reply_text(msg, parse_mode='Markdown')\n",
        "\n",
        "# التعامل مع مدخلات لوحة المفاتيح\n",
        "async def handle_keyboard_input(update: Update, context: ContextTypes.DEFAULT_TYPE):\n",
        "    text = update.message.text.strip().upper()  # تحويل النص إلى حروف كبيرة وإزالة المسافات\n",
        "    awaiting = context.user_data.get('awaiting')\n",
        "\n",
        "    # استعلام عن شعبة\n",
        "    if text == '📋 استعلام عن شعبة':\n",
        "        await update.message.reply_text(\"💬 اكتب رمز المقرر للاستعلام عن جميع شعبه، مثل: MGT408\")\n",
        "        context.user_data['awaiting'] = 'section_info'\n",
        "\n",
        "    elif awaiting == 'section_info':\n",
        "        context.user_data['awaiting'] = None\n",
        "        course_code = text.strip()  # التأكد من إزالة المسافات الزائدة\n",
        "        sections = data_sections[data_sections['رمزالمقرر'].str.upper().str.strip() == course_code]  # البحث باستخدام حروف كبيرة\n",
        "\n",
        "        if not sections.empty:\n",
        "            msg = f\"📋 *تفاصيل المقرر {course_code}:*\\n\"\n",
        "            for _, sec in sections.iterrows():\n",
        "                msg += (\n",
        "                    f\"\\n🔹 رقم الشعبة: {sec['الشعبة']}\\n\"\n",
        "                    f\"🔹 الرقم المرجعي: {sec['الرقم المرجعي']}\\n\"\n",
        "                    f\"🔹 اسم المقرر: {sec['أسم المقرر']}\\n\"\n",
        "                    f\"🔹 نوع الشعبة: {sec['نوع الشعبة']}\\n\"\n",
        "                    f\"🔹 الوقت: {sec['الوقت']}\\n\"\n",
        "                    f\"🔹 الأيام: {sec['الايام']}\\n\"\n",
        "                    f\"🔹 المبنى: {sec['المبنى']}\\n\"\n",
        "                    f\"🔹 رقم القاعة: {sec['رقم القاعة']}\\n\\n\"\n",
        "                )\n",
        "            keyboard = [['استعلام عن شعبة أخرى', '🔙 رجوع']]\n",
        "            reply_markup = ReplyKeyboardMarkup(keyboard, resize_keyboard=True)\n",
        "            await update.message.reply_text(msg, parse_mode='Markdown', reply_markup=reply_markup)\n",
        "        else:\n",
        "            await update.message.reply_text(\"⚠️ لا توجد شعب لهذا المقرر أو الرمز غير صحيح.\")\n",
        "\n",
        "    # استعلام عن شعبة أخرى\n",
        "    elif text == 'استعلام عن شعبة أخرى':\n",
        "        context.user_data['awaiting'] = 'section_info'\n",
        "        await update.message.reply_text(\"💬 اكتب رمز المقرر للاستعلام عن شعبته، مثل: MGT408\")\n",
        "\n",
        "    # استعلام عن مادة\n",
        "    elif text == '📚 استعلام عن مادة':\n",
        "        await update.message.reply_text(\"💬 اكتب رمز المادة للاستعلام عن تفاصيلها، مثل: MIS101\")\n",
        "        context.user_data['awaiting'] = 'course_info'\n",
        "\n",
        "    # استعلام عن مادة أخرى\n",
        "    elif text == 'استعلام عن مادة أخرى':\n",
        "        # إعادة تعيين حالة الانتظار إلى \"استعلام عن مادة\"\n",
        "        context.user_data['awaiting'] = 'course_info'\n",
        "        await update.message.reply_text(\"💬 اكتب رمز المادة للاستعلام عن تفاصيلها، مثل: MIS101\")\n",
        "\n",
        "    elif awaiting == 'course_info':\n",
        "        context.user_data['awaiting'] = None\n",
        "        course = data_courses[data_courses['رمز المادة'] == text]\n",
        "        if not course.empty:\n",
        "            row = course.iloc[0]\n",
        "            msg = f\"🔹 *{row['اسم المادة']}*\\nمتطلبات: {row['المتطلبات']}\\nعدد الساعات: {row['عدد الساعات']}\"\n",
        "            keyboard = [['استعلام عن مادة أخرى', '🔙 رجوع']]\n",
        "            reply_markup = ReplyKeyboardMarkup(keyboard, resize_keyboard=True)\n",
        "            await update.message.reply_text(msg, parse_mode='Markdown', reply_markup=reply_markup)\n",
        "        else:\n",
        "            await update.message.reply_text(\"⚠️ رمز المادة غير صحيح.\")\n",
        "\n",
        "    # المواد الاختيارية\n",
        "    elif text == '📋 المواد الاختيارية':\n",
        "        await handle_optional_menu(update, context)\n",
        "\n",
        "    elif text in ['تخصص MIS', 'تخصص MGT', 'تخصص MKT', 'تخصص FIN', 'تخصص ACC']:\n",
        "        major_map = {\n",
        "            'تخصص MIS': 'MIS',\n",
        "            'تخصص MGT': 'MGT',\n",
        "            'تخصص MKT': 'MKT',\n",
        "            'تخصص FIN': 'FIN',\n",
        "            'تخصص ACC': 'ACC'\n",
        "        }\n",
        "        await show_optional_by_major(update, major_map[text])\n",
        "\n",
        "    # الخطة الدراسية\n",
        "    elif text == '📖 الخطة الدراسية':\n",
        "        keyboard = [['2020 فما قبل', '2021 - 2023', '2024'], ['🔙 رجوع']]\n",
        "        reply_markup = ReplyKeyboardMarkup(keyboard, resize_keyboard=True)\n",
        "        context.user_data['awaiting'] = 'choose_plan_year'\n",
        "        await update.message.reply_text(\"📖 اختر دفعتك لعرض الخطة الدراسية المناسبة:\", reply_markup=reply_markup)\n",
        "\n",
        "    # إرسال الخطة الدراسية بناءً على اختيار المستخدم\n",
        "    elif awaiting == 'choose_plan_year':\n",
        "        context.user_data['awaiting'] = None\n",
        "        if text == '2020 فما قبل':\n",
        "            filename = 'الخطة 2020 فما قبل.pdf'\n",
        "        elif text == '2021 - 2023':\n",
        "            filename = 'الخطة 2021 - 2023.pdf'\n",
        "        elif text == '2024':\n",
        "            filename = 'الخطة 2024.pdf'\n",
        "        else:\n",
        "            await update.message.reply_text(\"❌ خيار غير صحيح، حاول مرة أخرى.\")\n",
        "            return\n",
        "\n",
        "        file_path = os.path.join(BASE_DIR, filename)\n",
        "        if os.path.exists(file_path):\n",
        "            await update.message.reply_document(\n",
        "                document=open(file_path, 'rb'),\n",
        "                caption=f\"📖 هذه هي الخطة الدراسية لدفعة {text} ✅\"\n",
        "            )\n",
        "        else:\n",
        "            await update.message.reply_text(\"⚠️ ملف الخطة غير موجود بجانب ملف البوت.\")\n",
        "\n",
        "    # دليل خدمات الطالب\n",
        "    elif text == '📖 دليل خدمات الطالب':\n",
        "        keyboard = [['تسجيل المقررات', 'سحب مادة'], ['🔙 رجوع']]\n",
        "        reply_markup = ReplyKeyboardMarkup(keyboard, resize_keyboard=True)\n",
        "        context.user_data['awaiting'] = 'student_guide'\n",
        "        await update.message.reply_text(\"📖 اختر الخدمة التي تحتاج دليلها:\", reply_markup=reply_markup)\n",
        "\n",
        "    # سحب مادة وتسجيل المقررات\n",
        "    elif awaiting == 'student_guide':\n",
        "        file_map = {\n",
        "            'تسجيل المقررات': 'تسجيل المقررات عبر منصة الارشاد الاكاديمي.pdf',\n",
        "            'سحب مادة': 'طريقة سحب مادة.pdf'\n",
        "        }\n",
        "\n",
        "        if text in file_map:\n",
        "            filename = file_map[text]\n",
        "            file_path = os.path.join(BASE_DIR, filename)\n",
        "            if os.path.exists(file_path):\n",
        "                await update.message.reply_document(\n",
        "                    document=open(file_path, 'rb'),\n",
        "                    caption=f\"📖 هذا هو الدليل المطلوب ✅\"\n",
        "                )\n",
        "            else:\n",
        "                await update.message.reply_text(\"⚠️ ملف الدليل غير موجود بجانب ملف البوت.\")\n",
        "        elif text == '🔙 رجوع':\n",
        "            await start(update, context)\n",
        "        else:\n",
        "            await update.message.reply_text(\"❌ خيار غير صحيح، حاول مرة أخرى.\")\n",
        "\n",
        "    # العودة\n",
        "    elif text == '🔙 رجوع':\n",
        "        await start(update, context)\n",
        "\n",
        "    # الخروج\n",
        "    elif text == '❌ خروج':\n",
        "        await update.message.reply_text(\"🚪 تم إنهاء الجلسة، لخدمتك مرة أخرى اضغط /start\", reply_markup=ReplyKeyboardRemove())\n",
        "\n",
        "\n",
        "\n",
        "\n",
        "# تشغيل البوت باستخدام asyncio\n",
        "if __name__ == '__main__':\n",
        "    app = ApplicationBuilder().token(TOKEN).build()\n",
        "    app.add_handler(CommandHandler(\"start\", start))\n",
        "    app.add_handler(MessageHandler(filters.TEXT & ~filters.COMMAND, handle_keyboard_input))\n",
        "    print(\"✅ البوت يعمل الآن بكامل المزايا...\")\n",
        "    asyncio.run(app.run_polling())\n"
      ],
      "metadata": {
        "colab": {
          "base_uri": "https://localhost:8080/"
        },
        "id": "_qdo-Zddbioo",
        "outputId": "ed763d0f-3dad-423f-cefc-0e22739fa262"
      },
      "execution_count": null,
      "outputs": [
        {
          "metadata": {
            "tags": null
          },
          "name": "stdout",
          "output_type": "stream",
          "text": [
            "✅ البوت يعمل الآن بكامل المزايا...\n"
          ]
        },
        {
          "output_type": "stream",
          "name": "stderr",
          "text": [
            "ERROR:telegram.ext.Application:No error handlers are registered, logging exception.\n",
            "Traceback (most recent call last):\n",
            "  File \"/usr/local/lib/python3.11/dist-packages/telegram/ext/_utils/networkloop.py\", line 115, in network_retry_loop\n",
            "    if not await do_action():\n",
            "           ^^^^^^^^^^^^^^^^^\n",
            "  File \"/usr/local/lib/python3.11/dist-packages/telegram/ext/_utils/networkloop.py\", line 108, in do_action\n",
            "    return action_cb_task.result()\n",
            "           ^^^^^^^^^^^^^^^^^^^^^^^\n",
            "  File \"/usr/lib/python3.11/asyncio/futures.py\", line 203, in result\n",
            "    raise self._exception.with_traceback(self._exception_tb)\n",
            "  File \"/usr/lib/python3.11/asyncio/tasks.py\", line 277, in __step\n",
            "    result = coro.send(None)\n",
            "             ^^^^^^^^^^^^^^^\n",
            "  File \"/usr/local/lib/python3.11/dist-packages/telegram/ext/_updater.py\", line 335, in polling_action_cb\n",
            "    updates = await self.bot.get_updates(\n",
            "              ^^^^^^^^^^^^^^^^^^^^^^^^^^^\n",
            "  File \"/usr/local/lib/python3.11/dist-packages/telegram/ext/_extbot.py\", line 658, in get_updates\n",
            "    updates = await super().get_updates(\n",
            "              ^^^^^^^^^^^^^^^^^^^^^^^^^^\n",
            "  File \"/usr/local/lib/python3.11/dist-packages/telegram/_bot.py\", line 4593, in get_updates\n",
            "    await self._post(\n",
            "  File \"/usr/local/lib/python3.11/dist-packages/telegram/_bot.py\", line 691, in _post\n",
            "    return await self._do_post(\n",
            "           ^^^^^^^^^^^^^^^^^^^^\n",
            "  File \"/usr/local/lib/python3.11/dist-packages/telegram/ext/_extbot.py\", line 362, in _do_post\n",
            "    return await super()._do_post(\n",
            "           ^^^^^^^^^^^^^^^^^^^^^^^\n",
            "  File \"/usr/local/lib/python3.11/dist-packages/telegram/_bot.py\", line 720, in _do_post\n",
            "    result = await request.post(\n",
            "             ^^^^^^^^^^^^^^^^^^^\n",
            "  File \"/usr/local/lib/python3.11/dist-packages/telegram/request/_baserequest.py\", line 197, in post\n",
            "    result = await self._request_wrapper(\n",
            "             ^^^^^^^^^^^^^^^^^^^^^^^^^^^^\n",
            "  File \"/usr/local/lib/python3.11/dist-packages/telegram/request/_baserequest.py\", line 355, in _request_wrapper\n",
            "    raise Conflict(message)\n",
            "telegram.error.Conflict: Conflict: terminated by other getUpdates request; make sure that only one bot instance is running\n",
            "ERROR:telegram.ext.Application:No error handlers are registered, logging exception.\n",
            "Traceback (most recent call last):\n",
            "  File \"/usr/local/lib/python3.11/dist-packages/telegram/ext/_utils/networkloop.py\", line 115, in network_retry_loop\n",
            "    if not await do_action():\n",
            "           ^^^^^^^^^^^^^^^^^\n",
            "  File \"/usr/local/lib/python3.11/dist-packages/telegram/ext/_utils/networkloop.py\", line 108, in do_action\n",
            "    return action_cb_task.result()\n",
            "           ^^^^^^^^^^^^^^^^^^^^^^^\n",
            "  File \"/usr/lib/python3.11/asyncio/futures.py\", line 203, in result\n",
            "    raise self._exception.with_traceback(self._exception_tb)\n",
            "  File \"/usr/lib/python3.11/asyncio/tasks.py\", line 277, in __step\n",
            "    result = coro.send(None)\n",
            "             ^^^^^^^^^^^^^^^\n",
            "  File \"/usr/local/lib/python3.11/dist-packages/telegram/ext/_updater.py\", line 335, in polling_action_cb\n",
            "    updates = await self.bot.get_updates(\n",
            "              ^^^^^^^^^^^^^^^^^^^^^^^^^^^\n",
            "  File \"/usr/local/lib/python3.11/dist-packages/telegram/ext/_extbot.py\", line 658, in get_updates\n",
            "    updates = await super().get_updates(\n",
            "              ^^^^^^^^^^^^^^^^^^^^^^^^^^\n",
            "  File \"/usr/local/lib/python3.11/dist-packages/telegram/_bot.py\", line 4593, in get_updates\n",
            "    await self._post(\n",
            "  File \"/usr/local/lib/python3.11/dist-packages/telegram/_bot.py\", line 691, in _post\n",
            "    return await self._do_post(\n",
            "           ^^^^^^^^^^^^^^^^^^^^\n",
            "  File \"/usr/local/lib/python3.11/dist-packages/telegram/ext/_extbot.py\", line 362, in _do_post\n",
            "    return await super()._do_post(\n",
            "           ^^^^^^^^^^^^^^^^^^^^^^^\n",
            "  File \"/usr/local/lib/python3.11/dist-packages/telegram/_bot.py\", line 720, in _do_post\n",
            "    result = await request.post(\n",
            "             ^^^^^^^^^^^^^^^^^^^\n",
            "  File \"/usr/local/lib/python3.11/dist-packages/telegram/request/_baserequest.py\", line 197, in post\n",
            "    result = await self._request_wrapper(\n",
            "             ^^^^^^^^^^^^^^^^^^^^^^^^^^^^\n",
            "  File \"/usr/local/lib/python3.11/dist-packages/telegram/request/_baserequest.py\", line 355, in _request_wrapper\n",
            "    raise Conflict(message)\n",
            "telegram.error.Conflict: Conflict: terminated by other getUpdates request; make sure that only one bot instance is running\n",
            "ERROR:telegram.ext.Application:No error handlers are registered, logging exception.\n",
            "Traceback (most recent call last):\n",
            "  File \"/usr/local/lib/python3.11/dist-packages/telegram/ext/_utils/networkloop.py\", line 115, in network_retry_loop\n",
            "    if not await do_action():\n",
            "           ^^^^^^^^^^^^^^^^^\n",
            "  File \"/usr/local/lib/python3.11/dist-packages/telegram/ext/_utils/networkloop.py\", line 108, in do_action\n",
            "    return action_cb_task.result()\n",
            "           ^^^^^^^^^^^^^^^^^^^^^^^\n",
            "  File \"/usr/lib/python3.11/asyncio/futures.py\", line 203, in result\n",
            "    raise self._exception.with_traceback(self._exception_tb)\n",
            "  File \"/usr/lib/python3.11/asyncio/tasks.py\", line 277, in __step\n",
            "    result = coro.send(None)\n",
            "             ^^^^^^^^^^^^^^^\n",
            "  File \"/usr/local/lib/python3.11/dist-packages/telegram/ext/_updater.py\", line 335, in polling_action_cb\n",
            "    updates = await self.bot.get_updates(\n",
            "              ^^^^^^^^^^^^^^^^^^^^^^^^^^^\n",
            "  File \"/usr/local/lib/python3.11/dist-packages/telegram/ext/_extbot.py\", line 658, in get_updates\n",
            "    updates = await super().get_updates(\n",
            "              ^^^^^^^^^^^^^^^^^^^^^^^^^^\n",
            "  File \"/usr/local/lib/python3.11/dist-packages/telegram/_bot.py\", line 4593, in get_updates\n",
            "    await self._post(\n",
            "  File \"/usr/local/lib/python3.11/dist-packages/telegram/_bot.py\", line 691, in _post\n",
            "    return await self._do_post(\n",
            "           ^^^^^^^^^^^^^^^^^^^^\n",
            "  File \"/usr/local/lib/python3.11/dist-packages/telegram/ext/_extbot.py\", line 362, in _do_post\n",
            "    return await super()._do_post(\n",
            "           ^^^^^^^^^^^^^^^^^^^^^^^\n",
            "  File \"/usr/local/lib/python3.11/dist-packages/telegram/_bot.py\", line 720, in _do_post\n",
            "    result = await request.post(\n",
            "             ^^^^^^^^^^^^^^^^^^^\n",
            "  File \"/usr/local/lib/python3.11/dist-packages/telegram/request/_baserequest.py\", line 197, in post\n",
            "    result = await self._request_wrapper(\n",
            "             ^^^^^^^^^^^^^^^^^^^^^^^^^^^^\n",
            "  File \"/usr/local/lib/python3.11/dist-packages/telegram/request/_baserequest.py\", line 355, in _request_wrapper\n",
            "    raise Conflict(message)\n",
            "telegram.error.Conflict: Conflict: terminated by other getUpdates request; make sure that only one bot instance is running\n",
            "ERROR:telegram.ext.Application:No error handlers are registered, logging exception.\n",
            "Traceback (most recent call last):\n",
            "  File \"/usr/local/lib/python3.11/dist-packages/telegram/ext/_utils/networkloop.py\", line 115, in network_retry_loop\n",
            "    if not await do_action():\n",
            "           ^^^^^^^^^^^^^^^^^\n",
            "  File \"/usr/local/lib/python3.11/dist-packages/telegram/ext/_utils/networkloop.py\", line 108, in do_action\n",
            "    return action_cb_task.result()\n",
            "           ^^^^^^^^^^^^^^^^^^^^^^^\n",
            "  File \"/usr/lib/python3.11/asyncio/futures.py\", line 203, in result\n",
            "    raise self._exception.with_traceback(self._exception_tb)\n",
            "  File \"/usr/lib/python3.11/asyncio/tasks.py\", line 277, in __step\n",
            "    result = coro.send(None)\n",
            "             ^^^^^^^^^^^^^^^\n",
            "  File \"/usr/local/lib/python3.11/dist-packages/telegram/ext/_updater.py\", line 335, in polling_action_cb\n",
            "    updates = await self.bot.get_updates(\n",
            "              ^^^^^^^^^^^^^^^^^^^^^^^^^^^\n",
            "  File \"/usr/local/lib/python3.11/dist-packages/telegram/ext/_extbot.py\", line 658, in get_updates\n",
            "    updates = await super().get_updates(\n",
            "              ^^^^^^^^^^^^^^^^^^^^^^^^^^\n",
            "  File \"/usr/local/lib/python3.11/dist-packages/telegram/_bot.py\", line 4593, in get_updates\n",
            "    await self._post(\n",
            "  File \"/usr/local/lib/python3.11/dist-packages/telegram/_bot.py\", line 691, in _post\n",
            "    return await self._do_post(\n",
            "           ^^^^^^^^^^^^^^^^^^^^\n",
            "  File \"/usr/local/lib/python3.11/dist-packages/telegram/ext/_extbot.py\", line 362, in _do_post\n",
            "    return await super()._do_post(\n",
            "           ^^^^^^^^^^^^^^^^^^^^^^^\n",
            "  File \"/usr/local/lib/python3.11/dist-packages/telegram/_bot.py\", line 720, in _do_post\n",
            "    result = await request.post(\n",
            "             ^^^^^^^^^^^^^^^^^^^\n",
            "  File \"/usr/local/lib/python3.11/dist-packages/telegram/request/_baserequest.py\", line 197, in post\n",
            "    result = await self._request_wrapper(\n",
            "             ^^^^^^^^^^^^^^^^^^^^^^^^^^^^\n",
            "  File \"/usr/local/lib/python3.11/dist-packages/telegram/request/_baserequest.py\", line 355, in _request_wrapper\n",
            "    raise Conflict(message)\n",
            "telegram.error.Conflict: Conflict: terminated by other getUpdates request; make sure that only one bot instance is running\n",
            "ERROR:telegram.ext.Application:No error handlers are registered, logging exception.\n",
            "Traceback (most recent call last):\n",
            "  File \"/usr/local/lib/python3.11/dist-packages/telegram/ext/_utils/networkloop.py\", line 115, in network_retry_loop\n",
            "    if not await do_action():\n",
            "           ^^^^^^^^^^^^^^^^^\n",
            "  File \"/usr/local/lib/python3.11/dist-packages/telegram/ext/_utils/networkloop.py\", line 108, in do_action\n",
            "    return action_cb_task.result()\n",
            "           ^^^^^^^^^^^^^^^^^^^^^^^\n",
            "  File \"/usr/lib/python3.11/asyncio/futures.py\", line 203, in result\n",
            "    raise self._exception.with_traceback(self._exception_tb)\n",
            "  File \"/usr/lib/python3.11/asyncio/tasks.py\", line 277, in __step\n",
            "    result = coro.send(None)\n",
            "             ^^^^^^^^^^^^^^^\n",
            "  File \"/usr/local/lib/python3.11/dist-packages/telegram/ext/_updater.py\", line 335, in polling_action_cb\n",
            "    updates = await self.bot.get_updates(\n",
            "              ^^^^^^^^^^^^^^^^^^^^^^^^^^^\n",
            "  File \"/usr/local/lib/python3.11/dist-packages/telegram/ext/_extbot.py\", line 658, in get_updates\n",
            "    updates = await super().get_updates(\n",
            "              ^^^^^^^^^^^^^^^^^^^^^^^^^^\n",
            "  File \"/usr/local/lib/python3.11/dist-packages/telegram/_bot.py\", line 4593, in get_updates\n",
            "    await self._post(\n",
            "  File \"/usr/local/lib/python3.11/dist-packages/telegram/_bot.py\", line 691, in _post\n",
            "    return await self._do_post(\n",
            "           ^^^^^^^^^^^^^^^^^^^^\n",
            "  File \"/usr/local/lib/python3.11/dist-packages/telegram/ext/_extbot.py\", line 362, in _do_post\n",
            "    return await super()._do_post(\n",
            "           ^^^^^^^^^^^^^^^^^^^^^^^\n",
            "  File \"/usr/local/lib/python3.11/dist-packages/telegram/_bot.py\", line 720, in _do_post\n",
            "    result = await request.post(\n",
            "             ^^^^^^^^^^^^^^^^^^^\n",
            "  File \"/usr/local/lib/python3.11/dist-packages/telegram/request/_baserequest.py\", line 197, in post\n",
            "    result = await self._request_wrapper(\n",
            "             ^^^^^^^^^^^^^^^^^^^^^^^^^^^^\n",
            "  File \"/usr/local/lib/python3.11/dist-packages/telegram/request/_baserequest.py\", line 355, in _request_wrapper\n",
            "    raise Conflict(message)\n",
            "telegram.error.Conflict: Conflict: terminated by other getUpdates request; make sure that only one bot instance is running\n",
            "ERROR:telegram.ext.Application:No error handlers are registered, logging exception.\n",
            "Traceback (most recent call last):\n",
            "  File \"/usr/local/lib/python3.11/dist-packages/telegram/ext/_utils/networkloop.py\", line 115, in network_retry_loop\n",
            "    if not await do_action():\n",
            "           ^^^^^^^^^^^^^^^^^\n",
            "  File \"/usr/local/lib/python3.11/dist-packages/telegram/ext/_utils/networkloop.py\", line 108, in do_action\n",
            "    return action_cb_task.result()\n",
            "           ^^^^^^^^^^^^^^^^^^^^^^^\n",
            "  File \"/usr/lib/python3.11/asyncio/futures.py\", line 203, in result\n",
            "    raise self._exception.with_traceback(self._exception_tb)\n",
            "  File \"/usr/lib/python3.11/asyncio/tasks.py\", line 277, in __step\n",
            "    result = coro.send(None)\n",
            "             ^^^^^^^^^^^^^^^\n",
            "  File \"/usr/local/lib/python3.11/dist-packages/telegram/ext/_updater.py\", line 335, in polling_action_cb\n",
            "    updates = await self.bot.get_updates(\n",
            "              ^^^^^^^^^^^^^^^^^^^^^^^^^^^\n",
            "  File \"/usr/local/lib/python3.11/dist-packages/telegram/ext/_extbot.py\", line 658, in get_updates\n",
            "    updates = await super().get_updates(\n",
            "              ^^^^^^^^^^^^^^^^^^^^^^^^^^\n",
            "  File \"/usr/local/lib/python3.11/dist-packages/telegram/_bot.py\", line 4593, in get_updates\n",
            "    await self._post(\n",
            "  File \"/usr/local/lib/python3.11/dist-packages/telegram/_bot.py\", line 691, in _post\n",
            "    return await self._do_post(\n",
            "           ^^^^^^^^^^^^^^^^^^^^\n",
            "  File \"/usr/local/lib/python3.11/dist-packages/telegram/ext/_extbot.py\", line 362, in _do_post\n",
            "    return await super()._do_post(\n",
            "           ^^^^^^^^^^^^^^^^^^^^^^^\n",
            "  File \"/usr/local/lib/python3.11/dist-packages/telegram/_bot.py\", line 720, in _do_post\n",
            "    result = await request.post(\n",
            "             ^^^^^^^^^^^^^^^^^^^\n",
            "  File \"/usr/local/lib/python3.11/dist-packages/telegram/request/_baserequest.py\", line 197, in post\n",
            "    result = await self._request_wrapper(\n",
            "             ^^^^^^^^^^^^^^^^^^^^^^^^^^^^\n",
            "  File \"/usr/local/lib/python3.11/dist-packages/telegram/request/_baserequest.py\", line 355, in _request_wrapper\n",
            "    raise Conflict(message)\n",
            "telegram.error.Conflict: Conflict: terminated by other getUpdates request; make sure that only one bot instance is running\n",
            "ERROR:telegram.ext.Application:No error handlers are registered, logging exception.\n",
            "Traceback (most recent call last):\n",
            "  File \"/usr/local/lib/python3.11/dist-packages/telegram/ext/_utils/networkloop.py\", line 115, in network_retry_loop\n",
            "    if not await do_action():\n",
            "           ^^^^^^^^^^^^^^^^^\n",
            "  File \"/usr/local/lib/python3.11/dist-packages/telegram/ext/_utils/networkloop.py\", line 108, in do_action\n",
            "    return action_cb_task.result()\n",
            "           ^^^^^^^^^^^^^^^^^^^^^^^\n",
            "  File \"/usr/lib/python3.11/asyncio/futures.py\", line 203, in result\n",
            "    raise self._exception.with_traceback(self._exception_tb)\n",
            "  File \"/usr/lib/python3.11/asyncio/tasks.py\", line 277, in __step\n",
            "    result = coro.send(None)\n",
            "             ^^^^^^^^^^^^^^^\n",
            "  File \"/usr/local/lib/python3.11/dist-packages/telegram/ext/_updater.py\", line 335, in polling_action_cb\n",
            "    updates = await self.bot.get_updates(\n",
            "              ^^^^^^^^^^^^^^^^^^^^^^^^^^^\n",
            "  File \"/usr/local/lib/python3.11/dist-packages/telegram/ext/_extbot.py\", line 658, in get_updates\n",
            "    updates = await super().get_updates(\n",
            "              ^^^^^^^^^^^^^^^^^^^^^^^^^^\n",
            "  File \"/usr/local/lib/python3.11/dist-packages/telegram/_bot.py\", line 4593, in get_updates\n",
            "    await self._post(\n",
            "  File \"/usr/local/lib/python3.11/dist-packages/telegram/_bot.py\", line 691, in _post\n",
            "    return await self._do_post(\n",
            "           ^^^^^^^^^^^^^^^^^^^^\n",
            "  File \"/usr/local/lib/python3.11/dist-packages/telegram/ext/_extbot.py\", line 362, in _do_post\n",
            "    return await super()._do_post(\n",
            "           ^^^^^^^^^^^^^^^^^^^^^^^\n",
            "  File \"/usr/local/lib/python3.11/dist-packages/telegram/_bot.py\", line 720, in _do_post\n",
            "    result = await request.post(\n",
            "             ^^^^^^^^^^^^^^^^^^^\n",
            "  File \"/usr/local/lib/python3.11/dist-packages/telegram/request/_baserequest.py\", line 197, in post\n",
            "    result = await self._request_wrapper(\n",
            "             ^^^^^^^^^^^^^^^^^^^^^^^^^^^^\n",
            "  File \"/usr/local/lib/python3.11/dist-packages/telegram/request/_baserequest.py\", line 355, in _request_wrapper\n",
            "    raise Conflict(message)\n",
            "telegram.error.Conflict: Conflict: terminated by other getUpdates request; make sure that only one bot instance is running\n",
            "ERROR:telegram.ext.Application:No error handlers are registered, logging exception.\n",
            "Traceback (most recent call last):\n",
            "  File \"/usr/local/lib/python3.11/dist-packages/telegram/ext/_utils/networkloop.py\", line 115, in network_retry_loop\n",
            "    if not await do_action():\n",
            "           ^^^^^^^^^^^^^^^^^\n",
            "  File \"/usr/local/lib/python3.11/dist-packages/telegram/ext/_utils/networkloop.py\", line 108, in do_action\n",
            "    return action_cb_task.result()\n",
            "           ^^^^^^^^^^^^^^^^^^^^^^^\n",
            "  File \"/usr/lib/python3.11/asyncio/futures.py\", line 203, in result\n",
            "    raise self._exception.with_traceback(self._exception_tb)\n",
            "  File \"/usr/lib/python3.11/asyncio/tasks.py\", line 277, in __step\n",
            "    result = coro.send(None)\n",
            "             ^^^^^^^^^^^^^^^\n",
            "  File \"/usr/local/lib/python3.11/dist-packages/telegram/ext/_updater.py\", line 335, in polling_action_cb\n",
            "    updates = await self.bot.get_updates(\n",
            "              ^^^^^^^^^^^^^^^^^^^^^^^^^^^\n",
            "  File \"/usr/local/lib/python3.11/dist-packages/telegram/ext/_extbot.py\", line 658, in get_updates\n",
            "    updates = await super().get_updates(\n",
            "              ^^^^^^^^^^^^^^^^^^^^^^^^^^\n",
            "  File \"/usr/local/lib/python3.11/dist-packages/telegram/_bot.py\", line 4593, in get_updates\n",
            "    await self._post(\n",
            "  File \"/usr/local/lib/python3.11/dist-packages/telegram/_bot.py\", line 691, in _post\n",
            "    return await self._do_post(\n",
            "           ^^^^^^^^^^^^^^^^^^^^\n",
            "  File \"/usr/local/lib/python3.11/dist-packages/telegram/ext/_extbot.py\", line 362, in _do_post\n",
            "    return await super()._do_post(\n",
            "           ^^^^^^^^^^^^^^^^^^^^^^^\n",
            "  File \"/usr/local/lib/python3.11/dist-packages/telegram/_bot.py\", line 720, in _do_post\n",
            "    result = await request.post(\n",
            "             ^^^^^^^^^^^^^^^^^^^\n",
            "  File \"/usr/local/lib/python3.11/dist-packages/telegram/request/_baserequest.py\", line 197, in post\n",
            "    result = await self._request_wrapper(\n",
            "             ^^^^^^^^^^^^^^^^^^^^^^^^^^^^\n",
            "  File \"/usr/local/lib/python3.11/dist-packages/telegram/request/_baserequest.py\", line 355, in _request_wrapper\n",
            "    raise Conflict(message)\n",
            "telegram.error.Conflict: Conflict: terminated by other getUpdates request; make sure that only one bot instance is running\n",
            "ERROR:telegram.ext.Application:No error handlers are registered, logging exception.\n",
            "Traceback (most recent call last):\n",
            "  File \"/usr/local/lib/python3.11/dist-packages/telegram/ext/_utils/networkloop.py\", line 115, in network_retry_loop\n",
            "    if not await do_action():\n",
            "           ^^^^^^^^^^^^^^^^^\n",
            "  File \"/usr/local/lib/python3.11/dist-packages/telegram/ext/_utils/networkloop.py\", line 108, in do_action\n",
            "    return action_cb_task.result()\n",
            "           ^^^^^^^^^^^^^^^^^^^^^^^\n",
            "  File \"/usr/lib/python3.11/asyncio/futures.py\", line 203, in result\n",
            "    raise self._exception.with_traceback(self._exception_tb)\n",
            "  File \"/usr/lib/python3.11/asyncio/tasks.py\", line 277, in __step\n",
            "    result = coro.send(None)\n",
            "             ^^^^^^^^^^^^^^^\n",
            "  File \"/usr/local/lib/python3.11/dist-packages/telegram/ext/_updater.py\", line 335, in polling_action_cb\n",
            "    updates = await self.bot.get_updates(\n",
            "              ^^^^^^^^^^^^^^^^^^^^^^^^^^^\n",
            "  File \"/usr/local/lib/python3.11/dist-packages/telegram/ext/_extbot.py\", line 658, in get_updates\n",
            "    updates = await super().get_updates(\n",
            "              ^^^^^^^^^^^^^^^^^^^^^^^^^^\n",
            "  File \"/usr/local/lib/python3.11/dist-packages/telegram/_bot.py\", line 4593, in get_updates\n",
            "    await self._post(\n",
            "  File \"/usr/local/lib/python3.11/dist-packages/telegram/_bot.py\", line 691, in _post\n",
            "    return await self._do_post(\n",
            "           ^^^^^^^^^^^^^^^^^^^^\n",
            "  File \"/usr/local/lib/python3.11/dist-packages/telegram/ext/_extbot.py\", line 362, in _do_post\n",
            "    return await super()._do_post(\n",
            "           ^^^^^^^^^^^^^^^^^^^^^^^\n",
            "  File \"/usr/local/lib/python3.11/dist-packages/telegram/_bot.py\", line 720, in _do_post\n",
            "    result = await request.post(\n",
            "             ^^^^^^^^^^^^^^^^^^^\n",
            "  File \"/usr/local/lib/python3.11/dist-packages/telegram/request/_baserequest.py\", line 197, in post\n",
            "    result = await self._request_wrapper(\n",
            "             ^^^^^^^^^^^^^^^^^^^^^^^^^^^^\n",
            "  File \"/usr/local/lib/python3.11/dist-packages/telegram/request/_baserequest.py\", line 355, in _request_wrapper\n",
            "    raise Conflict(message)\n",
            "telegram.error.Conflict: Conflict: terminated by other getUpdates request; make sure that only one bot instance is running\n",
            "ERROR:telegram.ext.Application:No error handlers are registered, logging exception.\n",
            "Traceback (most recent call last):\n",
            "  File \"/usr/local/lib/python3.11/dist-packages/telegram/ext/_utils/networkloop.py\", line 115, in network_retry_loop\n",
            "    if not await do_action():\n",
            "           ^^^^^^^^^^^^^^^^^\n",
            "  File \"/usr/local/lib/python3.11/dist-packages/telegram/ext/_utils/networkloop.py\", line 108, in do_action\n",
            "    return action_cb_task.result()\n",
            "           ^^^^^^^^^^^^^^^^^^^^^^^\n",
            "  File \"/usr/lib/python3.11/asyncio/futures.py\", line 203, in result\n",
            "    raise self._exception.with_traceback(self._exception_tb)\n",
            "  File \"/usr/lib/python3.11/asyncio/tasks.py\", line 277, in __step\n",
            "    result = coro.send(None)\n",
            "             ^^^^^^^^^^^^^^^\n",
            "  File \"/usr/local/lib/python3.11/dist-packages/telegram/ext/_updater.py\", line 335, in polling_action_cb\n",
            "    updates = await self.bot.get_updates(\n",
            "              ^^^^^^^^^^^^^^^^^^^^^^^^^^^\n",
            "  File \"/usr/local/lib/python3.11/dist-packages/telegram/ext/_extbot.py\", line 658, in get_updates\n",
            "    updates = await super().get_updates(\n",
            "              ^^^^^^^^^^^^^^^^^^^^^^^^^^\n",
            "  File \"/usr/local/lib/python3.11/dist-packages/telegram/_bot.py\", line 4593, in get_updates\n",
            "    await self._post(\n",
            "  File \"/usr/local/lib/python3.11/dist-packages/telegram/_bot.py\", line 691, in _post\n",
            "    return await self._do_post(\n",
            "           ^^^^^^^^^^^^^^^^^^^^\n",
            "  File \"/usr/local/lib/python3.11/dist-packages/telegram/ext/_extbot.py\", line 362, in _do_post\n",
            "    return await super()._do_post(\n",
            "           ^^^^^^^^^^^^^^^^^^^^^^^\n",
            "  File \"/usr/local/lib/python3.11/dist-packages/telegram/_bot.py\", line 720, in _do_post\n",
            "    result = await request.post(\n",
            "             ^^^^^^^^^^^^^^^^^^^\n",
            "  File \"/usr/local/lib/python3.11/dist-packages/telegram/request/_baserequest.py\", line 197, in post\n",
            "    result = await self._request_wrapper(\n",
            "             ^^^^^^^^^^^^^^^^^^^^^^^^^^^^\n",
            "  File \"/usr/local/lib/python3.11/dist-packages/telegram/request/_baserequest.py\", line 355, in _request_wrapper\n",
            "    raise Conflict(message)\n",
            "telegram.error.Conflict: Conflict: terminated by other getUpdates request; make sure that only one bot instance is running\n",
            "ERROR:telegram.ext.Application:No error handlers are registered, logging exception.\n",
            "Traceback (most recent call last):\n",
            "  File \"/usr/local/lib/python3.11/dist-packages/telegram/ext/_utils/networkloop.py\", line 115, in network_retry_loop\n",
            "    if not await do_action():\n",
            "           ^^^^^^^^^^^^^^^^^\n",
            "  File \"/usr/local/lib/python3.11/dist-packages/telegram/ext/_utils/networkloop.py\", line 108, in do_action\n",
            "    return action_cb_task.result()\n",
            "           ^^^^^^^^^^^^^^^^^^^^^^^\n",
            "  File \"/usr/lib/python3.11/asyncio/futures.py\", line 203, in result\n",
            "    raise self._exception.with_traceback(self._exception_tb)\n",
            "  File \"/usr/lib/python3.11/asyncio/tasks.py\", line 277, in __step\n",
            "    result = coro.send(None)\n",
            "             ^^^^^^^^^^^^^^^\n",
            "  File \"/usr/local/lib/python3.11/dist-packages/telegram/ext/_updater.py\", line 335, in polling_action_cb\n",
            "    updates = await self.bot.get_updates(\n",
            "              ^^^^^^^^^^^^^^^^^^^^^^^^^^^\n",
            "  File \"/usr/local/lib/python3.11/dist-packages/telegram/ext/_extbot.py\", line 658, in get_updates\n",
            "    updates = await super().get_updates(\n",
            "              ^^^^^^^^^^^^^^^^^^^^^^^^^^\n",
            "  File \"/usr/local/lib/python3.11/dist-packages/telegram/_bot.py\", line 4593, in get_updates\n",
            "    await self._post(\n",
            "  File \"/usr/local/lib/python3.11/dist-packages/telegram/_bot.py\", line 691, in _post\n",
            "    return await self._do_post(\n",
            "           ^^^^^^^^^^^^^^^^^^^^\n",
            "  File \"/usr/local/lib/python3.11/dist-packages/telegram/ext/_extbot.py\", line 362, in _do_post\n",
            "    return await super()._do_post(\n",
            "           ^^^^^^^^^^^^^^^^^^^^^^^\n",
            "  File \"/usr/local/lib/python3.11/dist-packages/telegram/_bot.py\", line 720, in _do_post\n",
            "    result = await request.post(\n",
            "             ^^^^^^^^^^^^^^^^^^^\n",
            "  File \"/usr/local/lib/python3.11/dist-packages/telegram/request/_baserequest.py\", line 197, in post\n",
            "    result = await self._request_wrapper(\n",
            "             ^^^^^^^^^^^^^^^^^^^^^^^^^^^^\n",
            "  File \"/usr/local/lib/python3.11/dist-packages/telegram/request/_baserequest.py\", line 355, in _request_wrapper\n",
            "    raise Conflict(message)\n",
            "telegram.error.Conflict: Conflict: terminated by other getUpdates request; make sure that only one bot instance is running\n",
            "ERROR:telegram.ext.Application:No error handlers are registered, logging exception.\n",
            "Traceback (most recent call last):\n",
            "  File \"/usr/local/lib/python3.11/dist-packages/telegram/ext/_utils/networkloop.py\", line 115, in network_retry_loop\n",
            "    if not await do_action():\n",
            "           ^^^^^^^^^^^^^^^^^\n",
            "  File \"/usr/local/lib/python3.11/dist-packages/telegram/ext/_utils/networkloop.py\", line 108, in do_action\n",
            "    return action_cb_task.result()\n",
            "           ^^^^^^^^^^^^^^^^^^^^^^^\n",
            "  File \"/usr/lib/python3.11/asyncio/futures.py\", line 203, in result\n",
            "    raise self._exception.with_traceback(self._exception_tb)\n",
            "  File \"/usr/lib/python3.11/asyncio/tasks.py\", line 277, in __step\n",
            "    result = coro.send(None)\n",
            "             ^^^^^^^^^^^^^^^\n",
            "  File \"/usr/local/lib/python3.11/dist-packages/telegram/ext/_updater.py\", line 335, in polling_action_cb\n",
            "    updates = await self.bot.get_updates(\n",
            "              ^^^^^^^^^^^^^^^^^^^^^^^^^^^\n",
            "  File \"/usr/local/lib/python3.11/dist-packages/telegram/ext/_extbot.py\", line 658, in get_updates\n",
            "    updates = await super().get_updates(\n",
            "              ^^^^^^^^^^^^^^^^^^^^^^^^^^\n",
            "  File \"/usr/local/lib/python3.11/dist-packages/telegram/_bot.py\", line 4593, in get_updates\n",
            "    await self._post(\n",
            "  File \"/usr/local/lib/python3.11/dist-packages/telegram/_bot.py\", line 691, in _post\n",
            "    return await self._do_post(\n",
            "           ^^^^^^^^^^^^^^^^^^^^\n",
            "  File \"/usr/local/lib/python3.11/dist-packages/telegram/ext/_extbot.py\", line 362, in _do_post\n",
            "    return await super()._do_post(\n",
            "           ^^^^^^^^^^^^^^^^^^^^^^^\n",
            "  File \"/usr/local/lib/python3.11/dist-packages/telegram/_bot.py\", line 720, in _do_post\n",
            "    result = await request.post(\n",
            "             ^^^^^^^^^^^^^^^^^^^\n",
            "  File \"/usr/local/lib/python3.11/dist-packages/telegram/request/_baserequest.py\", line 197, in post\n",
            "    result = await self._request_wrapper(\n",
            "             ^^^^^^^^^^^^^^^^^^^^^^^^^^^^\n",
            "  File \"/usr/local/lib/python3.11/dist-packages/telegram/request/_baserequest.py\", line 355, in _request_wrapper\n",
            "    raise Conflict(message)\n",
            "telegram.error.Conflict: Conflict: terminated by other getUpdates request; make sure that only one bot instance is running\n",
            "ERROR:telegram.ext.Application:No error handlers are registered, logging exception.\n",
            "Traceback (most recent call last):\n",
            "  File \"/usr/local/lib/python3.11/dist-packages/telegram/ext/_utils/networkloop.py\", line 115, in network_retry_loop\n",
            "    if not await do_action():\n",
            "           ^^^^^^^^^^^^^^^^^\n",
            "  File \"/usr/local/lib/python3.11/dist-packages/telegram/ext/_utils/networkloop.py\", line 108, in do_action\n",
            "    return action_cb_task.result()\n",
            "           ^^^^^^^^^^^^^^^^^^^^^^^\n",
            "  File \"/usr/lib/python3.11/asyncio/futures.py\", line 203, in result\n",
            "    raise self._exception.with_traceback(self._exception_tb)\n",
            "  File \"/usr/lib/python3.11/asyncio/tasks.py\", line 277, in __step\n",
            "    result = coro.send(None)\n",
            "             ^^^^^^^^^^^^^^^\n",
            "  File \"/usr/local/lib/python3.11/dist-packages/telegram/ext/_updater.py\", line 335, in polling_action_cb\n",
            "    updates = await self.bot.get_updates(\n",
            "              ^^^^^^^^^^^^^^^^^^^^^^^^^^^\n",
            "  File \"/usr/local/lib/python3.11/dist-packages/telegram/ext/_extbot.py\", line 658, in get_updates\n",
            "    updates = await super().get_updates(\n",
            "              ^^^^^^^^^^^^^^^^^^^^^^^^^^\n",
            "  File \"/usr/local/lib/python3.11/dist-packages/telegram/_bot.py\", line 4593, in get_updates\n",
            "    await self._post(\n",
            "  File \"/usr/local/lib/python3.11/dist-packages/telegram/_bot.py\", line 691, in _post\n",
            "    return await self._do_post(\n",
            "           ^^^^^^^^^^^^^^^^^^^^\n",
            "  File \"/usr/local/lib/python3.11/dist-packages/telegram/ext/_extbot.py\", line 362, in _do_post\n",
            "    return await super()._do_post(\n",
            "           ^^^^^^^^^^^^^^^^^^^^^^^\n",
            "  File \"/usr/local/lib/python3.11/dist-packages/telegram/_bot.py\", line 720, in _do_post\n",
            "    result = await request.post(\n",
            "             ^^^^^^^^^^^^^^^^^^^\n",
            "  File \"/usr/local/lib/python3.11/dist-packages/telegram/request/_baserequest.py\", line 197, in post\n",
            "    result = await self._request_wrapper(\n",
            "             ^^^^^^^^^^^^^^^^^^^^^^^^^^^^\n",
            "  File \"/usr/local/lib/python3.11/dist-packages/telegram/request/_baserequest.py\", line 355, in _request_wrapper\n",
            "    raise Conflict(message)\n",
            "telegram.error.Conflict: Conflict: terminated by other getUpdates request; make sure that only one bot instance is running\n",
            "ERROR:telegram.ext.Application:No error handlers are registered, logging exception.\n",
            "Traceback (most recent call last):\n",
            "  File \"/usr/local/lib/python3.11/dist-packages/telegram/ext/_utils/networkloop.py\", line 115, in network_retry_loop\n",
            "    if not await do_action():\n",
            "           ^^^^^^^^^^^^^^^^^\n",
            "  File \"/usr/local/lib/python3.11/dist-packages/telegram/ext/_utils/networkloop.py\", line 108, in do_action\n",
            "    return action_cb_task.result()\n",
            "           ^^^^^^^^^^^^^^^^^^^^^^^\n",
            "  File \"/usr/lib/python3.11/asyncio/futures.py\", line 203, in result\n",
            "    raise self._exception.with_traceback(self._exception_tb)\n",
            "  File \"/usr/lib/python3.11/asyncio/tasks.py\", line 277, in __step\n",
            "    result = coro.send(None)\n",
            "             ^^^^^^^^^^^^^^^\n",
            "  File \"/usr/local/lib/python3.11/dist-packages/telegram/ext/_updater.py\", line 335, in polling_action_cb\n",
            "    updates = await self.bot.get_updates(\n",
            "              ^^^^^^^^^^^^^^^^^^^^^^^^^^^\n",
            "  File \"/usr/local/lib/python3.11/dist-packages/telegram/ext/_extbot.py\", line 658, in get_updates\n",
            "    updates = await super().get_updates(\n",
            "              ^^^^^^^^^^^^^^^^^^^^^^^^^^\n",
            "  File \"/usr/local/lib/python3.11/dist-packages/telegram/_bot.py\", line 4593, in get_updates\n",
            "    await self._post(\n",
            "  File \"/usr/local/lib/python3.11/dist-packages/telegram/_bot.py\", line 691, in _post\n",
            "    return await self._do_post(\n",
            "           ^^^^^^^^^^^^^^^^^^^^\n",
            "  File \"/usr/local/lib/python3.11/dist-packages/telegram/ext/_extbot.py\", line 362, in _do_post\n",
            "    return await super()._do_post(\n",
            "           ^^^^^^^^^^^^^^^^^^^^^^^\n",
            "  File \"/usr/local/lib/python3.11/dist-packages/telegram/_bot.py\", line 720, in _do_post\n",
            "    result = await request.post(\n",
            "             ^^^^^^^^^^^^^^^^^^^\n",
            "  File \"/usr/local/lib/python3.11/dist-packages/telegram/request/_baserequest.py\", line 197, in post\n",
            "    result = await self._request_wrapper(\n",
            "             ^^^^^^^^^^^^^^^^^^^^^^^^^^^^\n",
            "  File \"/usr/local/lib/python3.11/dist-packages/telegram/request/_baserequest.py\", line 355, in _request_wrapper\n",
            "    raise Conflict(message)\n",
            "telegram.error.Conflict: Conflict: terminated by other getUpdates request; make sure that only one bot instance is running\n",
            "ERROR:telegram.ext.Application:No error handlers are registered, logging exception.\n",
            "Traceback (most recent call last):\n",
            "  File \"/usr/local/lib/python3.11/dist-packages/telegram/ext/_utils/networkloop.py\", line 115, in network_retry_loop\n",
            "    if not await do_action():\n",
            "           ^^^^^^^^^^^^^^^^^\n",
            "  File \"/usr/local/lib/python3.11/dist-packages/telegram/ext/_utils/networkloop.py\", line 108, in do_action\n",
            "    return action_cb_task.result()\n",
            "           ^^^^^^^^^^^^^^^^^^^^^^^\n",
            "  File \"/usr/lib/python3.11/asyncio/futures.py\", line 203, in result\n",
            "    raise self._exception.with_traceback(self._exception_tb)\n",
            "  File \"/usr/lib/python3.11/asyncio/tasks.py\", line 277, in __step\n",
            "    result = coro.send(None)\n",
            "             ^^^^^^^^^^^^^^^\n",
            "  File \"/usr/local/lib/python3.11/dist-packages/telegram/ext/_updater.py\", line 335, in polling_action_cb\n",
            "    updates = await self.bot.get_updates(\n",
            "              ^^^^^^^^^^^^^^^^^^^^^^^^^^^\n",
            "  File \"/usr/local/lib/python3.11/dist-packages/telegram/ext/_extbot.py\", line 658, in get_updates\n",
            "    updates = await super().get_updates(\n",
            "              ^^^^^^^^^^^^^^^^^^^^^^^^^^\n",
            "  File \"/usr/local/lib/python3.11/dist-packages/telegram/_bot.py\", line 4593, in get_updates\n",
            "    await self._post(\n",
            "  File \"/usr/local/lib/python3.11/dist-packages/telegram/_bot.py\", line 691, in _post\n",
            "    return await self._do_post(\n",
            "           ^^^^^^^^^^^^^^^^^^^^\n",
            "  File \"/usr/local/lib/python3.11/dist-packages/telegram/ext/_extbot.py\", line 362, in _do_post\n",
            "    return await super()._do_post(\n",
            "           ^^^^^^^^^^^^^^^^^^^^^^^\n",
            "  File \"/usr/local/lib/python3.11/dist-packages/telegram/_bot.py\", line 720, in _do_post\n",
            "    result = await request.post(\n",
            "             ^^^^^^^^^^^^^^^^^^^\n",
            "  File \"/usr/local/lib/python3.11/dist-packages/telegram/request/_baserequest.py\", line 197, in post\n",
            "    result = await self._request_wrapper(\n",
            "             ^^^^^^^^^^^^^^^^^^^^^^^^^^^^\n",
            "  File \"/usr/local/lib/python3.11/dist-packages/telegram/request/_baserequest.py\", line 355, in _request_wrapper\n",
            "    raise Conflict(message)\n",
            "telegram.error.Conflict: Conflict: terminated by other getUpdates request; make sure that only one bot instance is running\n",
            "ERROR:telegram.ext.Application:No error handlers are registered, logging exception.\n",
            "Traceback (most recent call last):\n",
            "  File \"/usr/local/lib/python3.11/dist-packages/telegram/ext/_utils/networkloop.py\", line 115, in network_retry_loop\n",
            "    if not await do_action():\n",
            "           ^^^^^^^^^^^^^^^^^\n",
            "  File \"/usr/local/lib/python3.11/dist-packages/telegram/ext/_utils/networkloop.py\", line 108, in do_action\n",
            "    return action_cb_task.result()\n",
            "           ^^^^^^^^^^^^^^^^^^^^^^^\n",
            "  File \"/usr/lib/python3.11/asyncio/futures.py\", line 203, in result\n",
            "    raise self._exception.with_traceback(self._exception_tb)\n",
            "  File \"/usr/lib/python3.11/asyncio/tasks.py\", line 277, in __step\n",
            "    result = coro.send(None)\n",
            "             ^^^^^^^^^^^^^^^\n",
            "  File \"/usr/local/lib/python3.11/dist-packages/telegram/ext/_updater.py\", line 335, in polling_action_cb\n",
            "    updates = await self.bot.get_updates(\n",
            "              ^^^^^^^^^^^^^^^^^^^^^^^^^^^\n",
            "  File \"/usr/local/lib/python3.11/dist-packages/telegram/ext/_extbot.py\", line 658, in get_updates\n",
            "    updates = await super().get_updates(\n",
            "              ^^^^^^^^^^^^^^^^^^^^^^^^^^\n",
            "  File \"/usr/local/lib/python3.11/dist-packages/telegram/_bot.py\", line 4593, in get_updates\n",
            "    await self._post(\n",
            "  File \"/usr/local/lib/python3.11/dist-packages/telegram/_bot.py\", line 691, in _post\n",
            "    return await self._do_post(\n",
            "           ^^^^^^^^^^^^^^^^^^^^\n",
            "  File \"/usr/local/lib/python3.11/dist-packages/telegram/ext/_extbot.py\", line 362, in _do_post\n",
            "    return await super()._do_post(\n",
            "           ^^^^^^^^^^^^^^^^^^^^^^^\n",
            "  File \"/usr/local/lib/python3.11/dist-packages/telegram/_bot.py\", line 720, in _do_post\n",
            "    result = await request.post(\n",
            "             ^^^^^^^^^^^^^^^^^^^\n",
            "  File \"/usr/local/lib/python3.11/dist-packages/telegram/request/_baserequest.py\", line 197, in post\n",
            "    result = await self._request_wrapper(\n",
            "             ^^^^^^^^^^^^^^^^^^^^^^^^^^^^\n",
            "  File \"/usr/local/lib/python3.11/dist-packages/telegram/request/_baserequest.py\", line 355, in _request_wrapper\n",
            "    raise Conflict(message)\n",
            "telegram.error.Conflict: Conflict: terminated by other getUpdates request; make sure that only one bot instance is running\n"
          ]
        }
      ]
    }
  ]
}